Workbook

Sheet Circuitos
A1: SALA DE CULTIVO | B1: QUANTIDADE | C1: Ci | D1: P (W) | E1: I (A)
A2: Nebulizador | B2: 2 | C2: c1 | D2: 700 | E2: =D2/220 -> 3.1818182
A3: Nebulizador | B3: 3 | C3: c2 | D3: 1050 | E3: =D3/220 -> 4.7727273
A4: Exaustor | B4: 1 | C4: c3 | D4: 1120 | E4: =D4/220 -> 5.0909091
A5: Exaustor | B5: 1 | C5: c4 | D5: 1120 | E5: =D5/220 -> 5.0909091
A6: Exaustor | B6: 1 | C6: c5 | D6: 1120 | E6: =D6/220 -> 5.0909091
A7: Exaustor | B7: 1 | C7: c6 | D7: 1120 | E7: =D7/220 -> 5.0909091
A8: Exaustor | B8: 1 | C8: c7 | D8: 1120 | E8: =D8/220 -> 5.0909091
A9: Exaustor | B9: 1 | C9: c8 | D9: 1120 | E9: =D9/220 -> 5.0909091
A10: Termostato | B10: 1 | C10: c9 | D10: 1500 | E10: =D10/220 -> 6.8181818
A11: Tomada | B11: 1 | C11: c10 | D11: 2200 | E11: =D11/220 -> 10
A12: Tomada | B12: 1 | C12: c11 | D12: 2200 | E12: =D12/220 -> 10
A13: Tomada | B13: 1 | C13: c12 | D13: 2200 | E13: =D13/220 -> 10
... A15: Tomada | B15: 1 | C15: c14 | D15: 2200 | E15: =D15/220 -> 10
A16: CORRIDA MICELIAL
A17: Aquecedor | B17: 1 | C17: c15 | D17: 3000 | E17: =D17/220 -> 13.636364
A18: Aquecedor | B18: 1 | C18: c16 | D18: 3000 | E18: =D18/220 -> 13.636364
A19: Aquecedor | B19: 1 | C19: c17 | D19: 3000 | E19: =D19/220 -> 13.636364
A20: Aquecedor | B20: 1 | C20: c18 | D20: 3000 | E20: =D20/220 -> 13.636364
A21: Aquecedor | B21: 1 | C21: c19 | D21: 3000 | E21: =D21/220 -> 13.636364
A22: Umidificador | B22: 3 | C22: c20 | D22: 1350 | E22: =D22/220 -> 6.1363636
A23: Umidificador | B23: 2 | C23: c21 | D23: 900 | E23: =D23/220 -> 4.0909091
A24: Tomada | B24: 1 | C24: c22 | D24: 2200 | E24: =D24/220 -> 10
A25: Tomada | B25: 1 | C25: c23 | D25: 2200 | E25: =D25/220 -> 10
A26: Tomada | B26: 1 | C26: c24 | D26: 2200 | E26: =D26/220 -> 10
A27: Tomada | B27: 1 | C27: c25 | D27: 2200 | E27: =D27/220 -> 10
A28: LABORÁTORIO
A29: Fluxo laminar horizontal | B29: 2 | C29: c26 | D29: 1140 | E29: =D29/220 -> 5.1818182
A30: Autoclave | B30: 1 | C30: c27 | D30: 9000 | E30: =D30/220 -> 40.909091
A31: Autoclave | B31: 1 | C31: c28 | D31: 9000 | E31: =D31/220 -> 40.909091
A32: Autoclave | B32: 1 | C32: c29 | D32: 9000 | E32: =D32/220 -> 40.909091
A33: Autoclave | B33: 1 | C33: c30 | D33: 9000 | E33: =D33/220 -> 40.909091
A34: Estufa | B34: 1 | C34: c31 | D34: 4000 | E34: =D34/220 -> 18.181818
A35: Estufa | B35: 1 | C35: c32 | D35: 4000 | E35: =D35/220 -> 18.181818
A36: Estufa | B36: 1 | C36: c33 | D36: 4000 | E36: =D36/220 -> 18.181818
A37: Estufa | B37: 1 | C37: c34 | D37: 4000 | E37: =D37/220 -> 18.181818
A38: Destilador | B38: 1 | C38: c35 | D38: 70000 | E38: =D38/220 -> 318.18182
A39: Freezer | B39: 5 | C39: c36 | D39: 1080 | E39: =D39/220 -> 4.9090909
A40: Freezer | B40: 2 | C40: c37 | D40: 720 | E40: =D40/220 -> 3.2727273
... A58: Tomadas | B58: 1 | C58: c55 | D58: 2200 | E58: =D58/220 -> 10
...

Sheet Metodo 1
A1: SALA DE CULTIVO | B1: QUANTIDADE | C1: MÉTODO | D1: Ci | E1: P (W) | F1: I (A) | G1: Ø (nn^2) | H1: Ø neutro | I1: Ø terra | J1: Disjuntor
A2: Nebulizador | B2: 2 | C2: B1 | D2: c1 | E2: 700 | F2: =E2/220 -> 3.1818182 | G2: 2.5 | H2: 2.5 | I2: 2.5 | J2: 6
A3: Nebulizador | B3: 3 | C3: B1 | D3: c2 | E3: 1050 | F3: =E3/220 -> 4.7727273 | G3: 2.5 | H3: 2.5 | I3: 2.5 | J3: 6
A4: Exaustor | B4: 1 | C4: B1 | D4: c3 | E4: 1120 | F4: =E4/220 -> 5.0909091 | G4: 2.5 | H4: 2.5 | I4: 2.5 | J4: 6
A5: Exaustor | B5: 1 | C5: B1 | D5: c4 | E5: 1120 | F5: =E5/220 -> 5.0909091 | G5: 2.5 | H5: 2.5 | I5: 2.5 | J5: 6
A6: Exaustor | B6: 1 | C6: B1 | D6: c5 | E6: 1120 | F6: =E6/220 -> 5.0909091 | G6: 2.5 | H6: 2.5 | I6: 2.5 | J6: 6
A7: Exaustor | B7: 1 | C7: B1 | D7: c6 | E7: 1120 | F7: =E7/220 -> 5.0909091 | G7: 2.5 | H7: 2.5 | I7: 2.5 | J7: 6
A8: Exaustor | B8: 1 | C8: B1 | D8: c7 | E8: 1120 | F8: =E8/220 -> 5.0909091 | G8: 2.5 | H8: 2.5 | I8: 2.5 | J8: 6
A9: Exaustor | B9: 1 | C9: B1 | D9: c8 | E9: 1120 | F9: =E9/220 -> 5.0909091 | G9: 2.5 | H9: 2.5 | I9: 2.5 | J9: 6
A10: Termostato | B10: 1 | C10: B1 | D10: c9 | E10: 1500 | F10: =E10/220 -> 6.8181818 | G10: 2.5 | H10: 2.5 | I10: 2.5 | J10: 10
A11: Tomada | B11: 1 | C11: B1 | D11: c10 | E11: 2200 | F11: =E11/220 -> 10 | G11: 2.5 | H11: 2.5 | I11: 2.5 | J11: 12
A12: Tomada | B12: 1 | C12: B1 | D12: c11 | E12: 2200 | F12: =E12/220 -> 10 | G12: 2.5 | H12: 2.5 | I12: 2.5 | J12: 12
A13: Tomada | B13: 1 | C13: B1 | D13: c12 | E13: 2200 | F13: =E13/220 -> 10 | G13: 2.5 | H13: 2.5 | I13: 2.5 | J13: 12
... A15: Tomada | B15: 1 | C15: B1 | D15: c14 | E15: 2200 | F15: =E15/220 -> 10 | G15: 2.5 | H15: 2.5 | I15: 2.5 | J15: 12
A18: CORRIDA MICELIAL | B18: QUANTIDADE | C18: MÉTODO | D18: Ci | E18: P (W) | F18: I (A) | G18: Ø (nn^2) | H18: Ø neutro | I18: Ø terra | J18: Disjuntor
A19: Aquecedor | B19: 1 | C19: B1 | D19: c15 | E19: 3000 | F19: =E19/220 -> 13.636364 | G19: 2.5 | H19: 2.5 | I19: 2.5 | J19: 15
A20: Aquecedor | B20: 1 | C20: B1 | D20: c16 | E20: 3000 | F20: =E20/220 -> 13.636364 | G20: 2.5 | H20: 2.5 | I20: 2.5 | J20: 15
A21: Aquecedor | B21: 1 | C21: B1 | D21: c17 | E21: 3000 | F21: =E21/220 -> 13.636364 | G21: 2.5 | H21: 2.5 | I21: 2.5 | J21: 15
A22: Aquecedor | B22: 1 | C22: B1 | D22: c18 | E22: 3000 | F22: =E22/220 -> 13.636364 | G22: 2.5 | H22: 2.5 | I22: 2.5 | J22: 15
A23: Aquecedor | B23: 1 | C23: B1 | D23: c19 | E23: 3000 | F23: =E23/220 -> 13.636364 | G23: 2.5 | H23: 2.5 | I23: 2.5 | J23: 15
A24: Umidificador | B24: 3 | C24: B1 | D24: c20 | E24: 1350 | F24: =E24/220 -> 6.1363636 | G24: 2.5 | H24: 2.5 | I24: 2.5 | J24: 10
A25: Umidificador | B25: 2 | C25: B1 | D25: c21 | E25: 900 | F25: =E25/220 -> 4.0909091 | G25: 2.5 | H25: 2.5 | I25: 2.5 | J25: 6
A26: Tomada | B26: 1 | C26: B1 | D26: c22 | E26: 2200 | F26: =E26/220 -> 10 | G26: 2.5 | H26: 2.5 | I26: 2.5 | J26: 12
A27: Tomada | B27: 1 | C27: B1 | D27: c23 | E27: 2200 | F27: =E27/220 -> 10 | G27: 2.5 | H27: 2.5 | I27: 2.5 | J27: 12
A28: Tomada | B28: 1 | C28: B1 | D28: c24 | E28: 2200 | F28: =E28/220 -> 10 | G28: 2.5 | H28: 2.5 | I28: 2.5 | J28: 12
A29: Tomada | B29: 1 | C29: B1 | D29: c25 | E29: 2200 | F29: =E29/220 -> 10 | G29: 2.5 | H29: 2.5 | I29: 2.5 | J29: 12
A32: LABORÁTORIO | B32: QUANTIDADE | C32: MÉTODO | D32: Ci | E32: P (W) | F32: I (A) | G32: Ø (nn^2) | H32: Ø neutro | I32: Ø terra | J32: Disjuntor
A33: Fluxo laminar horizontal | B33: 2 | C33: B1 | D33: c26 | E33: 1140 | F33: =E33/220 -> 5.1818182 | G33: 2.5 | H33: 2.5 | I33: 2.5 | J33: 6
A34: Autoclave | B34: 1 | C34: B1 | D34: c27 | E34: 9000 | F34: =E34/220 -> 40.909091 | G34: 2.5 | H34: 2.5 | I34: 2.5 | J34: 50
A35: Autoclave | B35: 1 | C35: B1 | D35: c28 | E35: 9000 | F35: =E35/220 -> 40.909091 | G35: 2.5 | H35: 2.5 | I35: 2.5 | J35: 50
A36: Autoclave | B36: 1 | C36: B1 | D36: c29 | E36: 9000 | F36: =E36/220 -> 40.909091 | G36: 2.5 | H36: 2.5 | I36: 2.5 | J36: 50
A37: Autoclave | B37: 1 | C37: B1 | D37: c30 | E37: 9000 | F37: =E37/220 -> 40.909091 | G37: 2.5 | H37: 2.5 | I37: 2.5 | J37: 50
A38: Estufa | B38: 1 | C38: B1 | D38: c31 | E38: 4000 | F38: =E38/220 -> 18.181818 | G38: 2.5 | H38: 2.5 | I38: 2.5 | J38: 20
A39: Estufa | B39: 1 | C39: B1 | D39: c32 | E39: 4000 | F39: =E39/220 -> 18.181818 | G39: 2.5 | H39: 2.5 | I39: 2.5 | J39: 20
A40: Estufa | B40: 1 | C40: B1 | D40: c33 | E40: 4000 | F40: =E40/220 -> 18.181818 | G40: 2.5 | H40: 2.5 | I40: 2.5 | J40: 20
A41: Estufa | B41: 1 | C41: B1 | D41: c34 | E41: 4000 | F41: =E41/220 -> 18.181818 | G41: 2.5 | H41: 2.5 | I41: 2.5 | J41: 20
A42: Destilador | B42: 1 | C42: B1 | D42: c35 | E42: 70000 | F42: =E42/220 -> 318.18182 | G42: 2.5 | H42: 2.5 | I42: 2.5 | J42: 320
A43: Freezer | B43: 5 | C43: B1 | D43: c36 | E43: 1080 | F43: =E43/220 -> 4.9090909 | G43: 2.5 | H43: 2.5 | I43: 2.5 | J43: 6
A44: Freezer | B44: 2 | C44: B1 | D44: c37 | E44: 720 | F44: =E44/220 -> 3.2727273 | G44: 2.5 | H44: 2.5 | I44: 2.5 | J44: 6
... A62: Tomadas | B62: 1 | C62: B1 | D62: c55 | E62: 2200 | F62: =E62/220 -> 10 | G62: 2.5 | H62: 2.5 | I62: 2.5 | J62: 12
...

Sheet Metodo 2
A1: SALA DE CULTIVO | B1: QUANTIDADE | C1: MÉTODO | D1: Numero de Condutores carregados | E1: Ci | F1: P (W) | G1: I (A) | H1: Ø (nn^2) | I1: Ø neutro | J1: Ø terra | K1: Disjuntor
A2: Nebulizador | B2: 2 | C2: B1 | D2: 2 | E2: c1 | F2: 700 | G2: =F2/220 -> 3.1818182 | H2: 1.5 | I2: 1.5 | J2: 1.5 | K2: 6
A3: Nebulizador | B3: 3 | C3: B1 | D3: 2 | E3: c2 | F3: 1050 | G3: =F3/220 -> 4.7727273 | H3: 1.5 | I3: 1.5 | J3: 1.5 | K3: 6
A4: Exaustor | B4: 1 | C4: B1 | D4: 2 | E4: c3 | F4: 1120 | G4: =F4/220 -> 5.0909091 | H4: 1.5 | I4: 1.5 | J4: 1.5 | K4: 6
A5: Exaustor | B5: 1 | C5: B1 | D5: 2 | E5: c4 | F5: 1120 | G5: =F5/220 -> 5.0909091 | H5: 1.5 | I5: 1.5 | J5: 1.5 | K5: 6
A6: Exaustor | B6: 1 | C6: B1 | D6: 2 | E6: c5 | F6: 1120 | G6: =F6/220 -> 5.0909091 | H6: 1.5 | I6: 1.5 | J6: 1.5 | K6: 6
A7: Exaustor | B7: 1 | C7: B1 | D7: 2 | E7: c6 | F7: 1120 | G7: =F7/220 -> 5.0909091 | H7: 1.5 | I7: 1.5 | J7: 1.5 | K7: 6
A8: Exaustor | B8: 1 | C8: B1 | D8: 2 | E8: c7 | F8: 1120 | G8: =F8/220 -> 5.0909091 | H8: 1.5 | I8: 1.5 | J8: 1.5 | K8: 6
A9: Exaustor | B9: 1 | C9: B1 | D9: 2 | E9: c8 | F9: 1120 | G9: =F9/220 -> 5.0909091 | H9: 1.5 | I9: 1.5 | J9: 1.5 | K9: 6
A10: Termostato | B10: 1 | C10: B1 | D10: 2 | E10: c9 | F10: 1500 | G10: =F10/220 -> 6.8181818 | H10: 1.5 | I10: 1.5 | J10: 1.5 | K10: 10
A11: Tomada | B11: 1 | C11: B1 | D11: 2 | E11: c10 | F11: 2200 | G11: =F11/220 -> 10 | H11: 1.5 | I11: 1.5 | J11: 1.5 | K11: 12
A12: Tomada | B12: 1 | C12: B1 | D12: 2 | E12: c11 | F12: 2200 | G12: =F12/220 -> 10 | H12: 1.5 | I12: 1.5 | J12: 1.5 | K12: 12
A13: Tomada | B13: 1 | C13: B1 | D13: 2 | E13: c12 | F13: 2200 | G13: =F13/220 -> 10 | H13: 1.5 | I13: 1.5 | J13: 1.5 | K13: 12
... A15: Tomada | B15: 1 | C15: B1 | D15: 2 | E15: c14 | F15: 2200 | G15: =F15/220 -> 10 | H15: 1.5 | I15: 1.5 | J15: 1.5 | K15: 12
A18: CORRIDA MICELIAL | B18: QUANTIDADE | C18: MÉTODO | D18: Numero de Condutores carregados | E18: Ci | F18: P (W) | G18: I (A) | H18: Ø (nn^2) | I18: Ø neutro | J18: Ø terra | K18: Disjuntor
A19: Aquecedor | B19: 1 | C19: B1 | D19: 2 | E19: c15 | F19: 3000 | G19: =F19/220 -> 13.636364 | H19: 1.5 | I19: 1.5 | J19: 1.5 | K19: 15
A20: Aquecedor | B20: 1 | C20: B1 | D20: 2 | E20: c16 | F20: 3000 | G20: =F20/220 -> 13.636364 | H20: 1.5 | I20: 1.5 | J20: 1.5 | K20: 15
A21: Aquecedor | B21: 1 | C21: B1 | D21: 2 | E21: c17 | F21: 3000 | G21: =F21/220 -> 13.636364 | H21: 1.5 | I21: 1.5 | J21: 1.5 | K21: 15
A22: Aquecedor | B22: 1 | C22: B1 | D22: 2 | E22: c18 | F22: 3000 | G22: =F22/220 -> 13.636364 | H22: 1.5 | I22: 1.5 | J22: 1.5 | K22: 15
A23: Aquecedor | B23: 1 | C23: B1 | D23: 2 | E23: c19 | F23: 3000 | G23: =F23/220 -> 13.636364 | H23: 1.5 | I23: 1.5 | J23: 1.5 | K23: 15
A24: Umidificador | B24: 3 | C24: B1 | D24: 2 | E24: c20 | F24: 1350 | G24: =F24/220 -> 6.1363636 | H24: 1.5 | I24: 1.5 | J24: 1.5 | K24: 10
A25: Umidificador | B25: 2 | C25: B1 | D25: 2 | E25: c21 | F25: 900 | G25: =F25/220 -> 4.0909091 | H25: 1.5 | I25: 1.5 | J25: 1.5 | K25: 6
A26: Tomada | B26: 1 | C26: B1 | D26: 2 | E26: c22 | F26: 2200 | G26: =F26/220 -> 10 | H26: 1.5 | I26: 1.5 | J26: 1.5 | K26: 12
A27: Tomada | B27: 1 | C27: B1 | D27: 2 | E27: c23 | F27: 2200 | G27: =F27/220 -> 10 | H27: 1.5 | I27: 1.5 | J27: 1.5 | K27: 12
A28: Tomada | B28: 1 | C28: B1 | D28: 2 | E28: c24 | F28: 2200 | G28: =F28/220 -> 10 | H28: 1.5 | I28: 1.5 | J28: 1.5 | K28: 12
A29: Tomada | B29: 1 | C29: B1 | D29: 2 | E29: c25 | F29: 2200 | G29: =F29/220 -> 10 | H29: 1.5 | I29: 1.5 | J29: 1.5 | K29: 12
A32: LABORÁTORIO | B32: QUANTIDADE | C32: MÉTODO | D32: Numero de Condutores carregados | E32: Ci | F32: P (W) | G32: I (A) | H32: Ø (nn^2) | I32: Ø neutro | J32: Ø terra | K32: Disjuntor
A33: Fluxo laminar horizontal | B33: 2 | C33: B1 | D33: 2 | E33: c26 | F33: 1140 | G33: =F33/220 -> 5.1818182 | H33: 1.5 | I33: 1.5 | J33: 1.5 | K33: 6
A34: Autoclave | B34: 1 | C34: B1 | D34: 2 | E34: c27 | F34: 9000 | G34: =F34/220 -> 40.909091 | H34: 10 | I34: 10 | J34: 10 | K34: 50
A35: Autoclave | B35: 1 | C35: B1 | D35: 2 | E35: c28 | F35: 9000 | G35: =F35/220 -> 40.909091 | H35: 10 | I35: 10 | J35: 10 | K35: 50
A36: Autoclave | B36: 1 | C36: B1 | D36: 2 | E36: c29 | F36: 9000 | G36: =F36/220 -> 40.909091 | H36: 10 | I36: 10 | J36: 10 | K36: 50
A37: Autoclave | B37: 1 | C37: B1 | D37: 2 | E37: c30 | F37: 9000 | G37: =F37/220 -> 40.909091 | H37: 10 | I37: 10 | J37: 10 | K37: 50
A38: Estufa | B38: 1 | C38: B1 | D38: 2 | E38: c31 | F38: 4000 | G38: =F38/220 -> 18.181818 | H38: 2.5 | I38: 2.5 | J38: 2.5 | K38: 20
A39: Estufa | B39: 1 | C39: B1 | D39: 2 | E39: c32 | F39: 4000 | G39: =F39/220 -> 18.181818 | H39: 2.5 | I39: 2.5 | J39: 2.5 | K39: 20
A40: Estufa | B40: 1 | C40: B1 | D40: 2 | E40: c33 | F40: 4000 | G40: =F40/220 -> 18.181818 | H40: 2.5 | I40: 2.5 | J40: 2.5 | K40: 20
A41: Estufa | B41: 1 | C41: B1 | D41: 2 | E41: c34 | F41: 4000 | G41: =F41/220 -> 18.181818 | H41: 2.5 | I41: 2.5 | J41: 2.5 | K41: 20
A42: Destilador | B42: 1 | C42: B1 | D42: 2 | E42: c35 | F42: 70000 | G42: =F42/220 -> 318.18182 | H42: 185 | I42: 95 | J42: 95 | K42: 320
A43: Freezer | B43: 5 | C43: B1 | D43: 2 | E43: c36 | F43: 1080 | G43: =F43/220 -> 4.9090909 | H43: 1.5 | I43: 1.5 | J43: 1.5 | K43: 6
A44: Freezer | B44: 2 | C44: B1 | D44: 2 | E44: c37 | F44: 720 | G44: =F44/220 -> 3.2727273 | H44: 1.5 | I44: 1.5 | J44: 1.5 | K44: 6
... A62: Tomadas | B62: 1 | C62: B1 | D62: 2 | E62: c55 | F62: 2200 | G62: =F62/220 -> 10 | H62: 1.5 | I62: 1.5 | J62: 1.5 | K62: 12
...

Sheet Metodo 3
A1: Quadro 7
A2: SALA DE CULTIVO | B2: QUANTIDADE | C2: Ci | D2: P (W) | E2: I (A) | F2: Ø (nn^2) | G2: Ø neutro | H2: Ø terra | I2: Disjuntor
A3: Nebulizador | B3: 2 | C3: c1 | D3: 700 | E3: =D3/220 -> 3.1818182 | F3: 1.5 | G3: 1.5 | H3: 1.5 | I3: 6
A4: Nebulizador | B4: 3 | C4: c2 | D4: 1050 | E4: =D4/220 -> 4.7727273 | F4: 1.5 | G4: 1.5 | H4: 1.5 | I4: 6
A5: Exaustor | B5: 1 | C5: c3 | D5: 1120 | E5: =D5/220 -> 5.0909091 | F5: 1.5 | G5: 1.5 | H5: 1.5 | I5: 6
A6: Exaustor | B6: 1 | C6: c4 | D6: 1120 | E6: =D6/220 -> 5.0909091 | F6: 1.5 | G6: 1.5 | H6: 1.5 | I6: 6
A7: Exaustor | B7: 1 | C7: c5 | D7: 1120 | E7: =D7/220 -> 5.0909091 | F7: 1.5 | G7: 1.5 | H7: 1.5 | I7: 6
A8: Exaustor | B8: 1 | C8: c6 | D8: 1120 | E8: =D8/220 -> 5.0909091 | F8: 1.5 | G8: 1.5 | H8: 1.5 | I8: 6
A9: Exaustor | B9: 1 | C9: c7 | D9: 1120 | E9: =D9/220 -> 5.0909091 | F9: 1.5 | G9: 1.5 | H9: 1.5 | I9: 6
A10: Exaustor | B10: 1 | C10: c8 | D10: 1120 | E10: =D10/220 -> 5.0909091 | F10: 1.5 | G10: 1.5 | H10: 1.5 | I10: 6
A11: Termostato | B11: 1 | C11: c9 | D11: 1500 | E11: =D11/220 -> 6.8181818 | F11: 1.5 | G11: 1.5 | H11: 1.5 | I11: 10
A12: Tomada | B12: 1 | C12: c10 | D12: 2200 | E12: =D12/220 -> 10 | F12: 1.5 | G12: 1.5 | H12: 1.5 | I12: 12
A13: Tomada | B13: 1 | C13: c11 | D13: 2200 | E13: =D13/220 -> 10 | F13: 1.5 | G13: 1.5 | H13: 1.5 | I13: 12
A14: Tomada | B14: 1 | C14: c12 | D14: 2200 | E14: =D14/220 -> 10 | F14: 1.5 | G14: 1.5 | H14: 1.5 | I14: 12
... A16: Tomada | B16: 1 | C16: c14 | D16: 2200 | E16: =D16/220 -> 10 | F16: 1.5 | G16: 1.5 | H16: 1.5 | I16: 12
C17: Soma | D17: =SUM(D3:D16) -> 20970 | E17: =SUM(E3:E16) -> 95.318182
A19: Quadro 5
A20: CORRIDA MICELIAL | B20: QUANTIDADE | C20: Ci | D20: P (W) | E20: I (A) | F20: Ø (nn^2) | G20: Ø neutro | H20: Ø terra | I20: Disjuntor
A21: Aquecedor | B21: 1 | C21: c15 | D21: 3000 | E21: =D21/220 -> 13.636364 | F21: 1.5 | G21: 1.5 | H21: 1.5 | I21: 15
A22: Aquecedor | B22: 1 | C22: c16 | D22: 3000 | E22: =D22/220 -> 13.636364 | F22: 1.5 | G22: 1.5 | H22: 1.5 | I22: 15
A23: Aquecedor | B23: 1 | C23: c17 | D23: 3000 | E23: =D23/220 -> 13.636364 | F23: 1.5 | G23: 1.5 | H23: 1.5 | I23: 15
A24: Aquecedor | B24: 1 | C24: c18 | D24: 3000 | E24: =D24/220 -> 13.636364 | F24: 1.5 | G24: 1.5 | H24: 1.5 | I24: 15
A25: Aquecedor | B25: 1 | C25: c19 | D25: 3000 | E25: =D25/220 -> 13.636364 | F25: 1.5 | G25: 1.5 | H25: 1.5 | I25: 15
A26: Umidificador | B26: 3 | C26: c20 | D26: 1350 | E26: =D26/220 -> 6.1363636 | F26: 1.5 | G26: 1.5 | H26: 1.5 | I26: 10
A27: Umidificador | B27: 2 | C27: c21 | D27: 900 | E27: =D27/220 -> 4.0909091 | F27: 1.5 | G27: 1.5 | H27: 1.5 | I27: 6
A28: Tomada | B28: 1 | C28: c22 | D28: 2200 | E28: =D28/220 -> 10 | F28: 1.5 | G28: 1.5 | H28: 1.5 | I28: 12
A29: Tomada | B29: 1 | C29: c23 | D29: 2200 | E29: =D29/220 -> 10 | F29: 1.5 | G29: 1.5 | H29: 1.5 | I29: 12
A30: Tomada | B30: 1 | C30: c24 | D30: 2200 | E30: =D30/220 -> 10 | F30: 1.5 | G30: 1.5 | H30: 1.5 | I30: 12
A31: Tomada | B31: 1 | C31: c25 | D31: 2200 | E31: =D31/220 -> 10 | F31: 1.5 | G31: 1.5 | H31: 1.5 | I31: 12
C32: Soma | D32: =SUM(D21:D31) -> 26050 | E32: =SUM(E21:E31) -> 118.40909
A34: Quadro 6
A35: LABORÁTORIO | B35: QUANTIDADE | C35: Ci | D35: P (W) | E35: I (A) | F35: Ø (nn^2) | G35: Ø neutro | H35: Ø terra | I35: Disjuntor
A36: Fluxo laminar horizontal | B36: 2 | C36: c26 | D36: 1140 | E36: =D36/220 -> 5.1818182 | F36: 1.5 | G36: 1.5 | H36: 1.5 | I36: 6
A37: Autoclave | B37: 1 | C37: c27 | D37: 9000 | E37: =D37/220 -> 40.909091 | F37: 6 | G37: 6 | H37: 6 | I37: 50
A38: Autoclave | B38: 1 | C38: c28 | D38: 9000 | E38: =D38/220 -> 40.909091 | F38: 1.5 | G38: 1.5 | H38: 1.5 | I38: 50
A39: Autoclave | B39: 1 | C39: c29 | D39: 9000 | E39: =D39/220 -> 40.909091 | F39: 1.5 | G39: 1.5 | H39: 1.5 | I39: 50
A40: Autoclave | B40: 1 | C40: c30 | D40: 9000 | E40: =D40/220 -> 40.909091 | F40: 2.5 | G40: 2.5 | H40: 2.5 | I40: 50
A41: Estufa | B41: 1 | C41: c31 | D41: 4000 | E41: =D41/220 -> 18.181818 | F41: 1.5 | G41: 1.5 | H41: 1.5 | I41: 20
A42: Estufa | B42: 1 | C42: c32 | D42: 4000 | E42: =D42/220 -> 18.181818 | F42: 2.5 | G42: 2.5 | H42: 2.5 | I42: 20
A43: Estufa | B43: 1 | C43: c33 | D43: 4000 | E43: =D43/220 -> 18.181818 | F43: 2.5 | G43: 2.5 | H43: 2.5 | I43: 20
...

Sheet distancias
B4: Quadro geral até o quadro principal | E4: 51
D5: Wt | E5: =SUM(D9:D16) -> 529726
D6: PT KW | E6: =E5/1000 -> 529.726
B8: Do principal ate | D8: W | E8: A | F8: w.m | G8: Ø (nn^2) | H8: Ø neutro | I8: Ø terra | J8: Disjuntor
B9: Quadro 1 | C9: 31 | D9: ='Metodo 3'!D157 -> 21936 | E9: ='Metodo 3'!E157 -> 99.709091 | F9: =D9*(C9+$E$4) -> 1798752 | G9: 50 | H9: 25 | I9: 25 | J9: 125
B10: Quadro 2 | C10: 30 | D10: ='Metodo 3'!D171 -> 28536 | E10: ='Metodo 3'!E171 -> 129.70909 | F10: =D10*(C10+$E$4) -> 2311416 | G10: 70 | H10: 35 | I10: 35 | J10: 140
B11: Quadro 3 | C11: 12 | D11: ='Metodo 3'!D95 -> 97586 | E11: ='Metodo 3'!E95 -> 443.57273 | F11: =D11*(C11+$E$4) -> 6147918 | G11: 150 | H11: 70 | I11: 70 | J11: 450
B12: Quadro 4 | C12: 12 | D12: ='Metodo 3'!D146 -> 107900 | E12: ='Metodo 3'!E146 -> 490.45455 | F12: =D12*(C12+$E$4) -> 6797700 | G12: 185 | H12: 95 | I12: 95 | J12: 500
B13: Quadro 5 | C13: 15 | D13: ='Metodo 3'!D32 -> 26050 | E13: ='Metodo 3'!E32 -> 118.40909 | F13: =D13*(C13+$E$4) -> 1719300 | G13: 50 | H13: 25 | I13: 25 | J13: 125
B14: Quadro 6 | C14: 17 | D14: ='Metodo 3'!D66 -> 155748 | E14: ='Metodo 3'!E66 -> 707.94545 | F14: =D14*(C14+$E$4) -> 10590864 | G14: 300 | H14: 150 | I14: 150 | J14: 750
B15: Quadro 7 | C15: 22 | D15: ='Metodo 3'!D17 -> 20970 | E15: ='Metodo 3'!E17 -> 95.318182 | F15: =D15*(C15+$E$4) -> 1530810 | G15: 50 | H15: 25 | I15: 25 | J15: 100
B16: Quadro 8 | C16: 21 | D16: ='Metodo 3'!D119 -> 71000 | E16: ='Metodo 3'!E119 -> 322.72727 | F16: =D16*(C16+$E$4) -> 5112000 | G16: 150 | H16: 70 | I16: 70 | J16: 350
B20: Quadro 1 até | F20: w.m | G20: Ø (nn^2)
B21: Tomadas | C21: c124 | D21: 12 | E21: 2200 | F21: =E21*D21 -> 26400 | G21: 1.5
B22: Tomadas | C22: c125 | D22: 11 | E22: 2200 | F22: =E22*D22 -> 24200 | G22: 1.5
B23: Tomadas | C23: c126 | D23: 10 | E23: 2200 | F23: =E23*D23 -> 22000 | G23: 1.5
B24: Tomadas | C24: c127 | D24: 12 | E24: 2200 | F24: =E24*D24 -> 26400 | G24: 1.5
B25: Tomadas | C25: c128 | D25: 11 | E25: 2200 | F25: =E25*D25 -> 24200 | G25: 1.5
B26: Tomadas | C26: c129 | D26: 10 | E26: 2200 | F26: =E26*D26 -> 22000 | G26: 1.5
B27: Ar-condionado | C27: c130 | D27: 16 | E27: 8736 | F27: =E27*D27 -> 139776 | G27: 6
D28: Soma | E28: =SUM(E21:E27) -> 21936 | F28: =SUM(F21:F27) -> 284976
B31: Quadro 2 até | F31: w.m | G31: Ø (nn^2)
B32: Ar-condionado | C32: c131 | D32: 15 | E32: 8736 | F32: =E32*D32 -> 131040 | G32: 6
B33: Tomadas | C33: c132 | D33: 16 | E33: 2200 | F33: =E33*D33 -> 35200 | G33: 1.5
B34: Tomadas | C34: c133 | D34: 16 | E34: 2200 | F34: =E34*D34 -> 35200 | G34: 1.5
B35: Tomadas | C35: c134 | D35: 15 | E35: 2200 | F35: =E35*D35 -> 33000 | G35: 1.5
B36: Tomadas | C36: c135 | D36: 14 | E36: 2200 | F36: =E36*D36 -> 30800 | G36: 1.5
B37: Tomadas | C37: c136 | D37: 14 | E37: 2200 | F37: =E37*D37 -> 30800 | G37: 1.5
B38: Tomadas | C38: c137 | D38: 13 | E38: 2200 | F38: =E38*D38 -> 28600 | G38: 1.5
B39: Tomadas | C39: c138 | D39: 13 | E39: 2200 | F39: =E39*D39 -> 28600 | G39: 1.5
B40: Tomadas | C40: c139 | D40: 13 | E40: 2200 | F40: =E40*D40 -> 28600 | G40: 1.5
B41: Tomadas | C41: c140 | D41: 13 | E41: 2200 | F41: =E41*D41 -> 28600 | G41: 1.5
D42: Soma | E42: =SUM(E32:E41) -> 28536 | F42: =SUM(F32:F41) -> 410440
B45: Quadro 3 até | F45: w.m | G45: Ø (nn^2)
B46: Esteira | C46: c56 | D46: 37 | E46: 900 | F46: =E46*D46 -> 33300 | G46: 1.5
B47: Misturador | C47: c57 | D47: 27 | E47: 10725 | F47: =E47*D47 -> 289575 | G47: 16
B48: Misturador | C48: c58 | D48: 29 | E48: 10725 | F48: =E48*D48 -> 311025 | G48: 16
B49: Misturador | C49: c59 | D49: 32 | E49: 10725 | F49: =E49*D49 -> 343200 | G49: 16
B50: Misturador | C50: c60 | D50: 19 | E50: 10725 | F50: =E50*D50 -> 203775 | G50: 16
B51: Misturador | C51: c61 | D51: 24 | E51: 10725 | F51: =E51*D51 -> 257400 | G51: 16
...

Sheet Iluminotecnica
B1: Area | C1: Nivel de Luminamento | D1: Lumens | E1: Altura do Pé direito | F1: Plano util de trabalho | G1: Plano de altura das luminarias | H1: Distancia Teorica | I1: Comprimento | J1: Número de luminárias do comprimento | K1: Largura | L1: Número de luminárias da largura | M1: Número total de luminárias | N1: Cálculo do fluxo luminoso por luminária | O1: Horas Ligado | P1: w | Q1: w do conjunto | R1: wh | S1: Kwh
A2: Sala de Cultivo | B2: 370 | C2: 1200 | D2: =(B2*C2)/0.5 -> 888000 | E2: 6 | F2: 1 | G2: 2 | H2: =1.5*(E2-F2-G2) -> 4.5 | I2: 24.7 | J2: =I2/H2 -> 5.4888889 | K2: 15 | L2: =K2/H2 -> 3.3333333 | M2: =J2*L2 -> 18.296296 | N2: =D2/M2 -> 48534.413 | O2: 12 | P2: 100 + 200 | Q2: =300*M2 -> 5488.8889 | R2: =Q2*O2 -> 65866.667 | S2: =R2/1000 -> 65.866667
A3: Corrida Micelial | B3: 225 | C3: 0 | D3: =(B3*C3)/0.5 -> 0 | E3: 6 | F3: 1 | G3: 2 | H3: =1.5*(E3-F3-G3) -> 4.5 | I3: 15 | J3: =I3/H3 -> 3.3333333 | K3: 15 | L3: =K3/H3 -> 3.3333333 | M3: =J3*L3 -> 11.111111 | N3: =D3/M3 -> 0 | O3: 0 | P3: 0 | Q3: =P3*M3 -> 0 | R3: =Q3*O3 -> 0 | S3: =R3/1000 -> 0
A4: Laboratorio | B4: 150 | C4: 300 | D4: =(B4*C4)/0.5 -> 90000 | E4: 6 | F4: 1.4 | G4: 2.5 | H4: =1.5*(E4-F4-G4) -> 3.15 | I4: 10 | J4: =I4/H4 -> 3.1746032 | K4: 15 | L4: =K4/H4 -> 4.7619048 | M4: =J4*L4 -> 15.117158 | N4: =D4/M4 -> 5953.5 | O4: 8 | P4: 60 | Q4: =P4*M4 -> 907.02948 | R4: =Q4*O4 -> 7256.2358 | S4: =R4/1000 -> 7.2562358
A5: Preparo do Substrato | B5: 904 | C5: 750 | D5: =(B5*C5)/0.5 -> 1356000 | E5: 6 | F5: 1.4 | G5: 0.3 | H5: =1.5*(E5-F5-G5) -> 6.45 | I5: 30.15 | J5: =I5/H5 -> 4.6744186 | K5: 30 | L5: =K5/H5 -> 4.6511628 | M5: =J5*L5 -> 21.741482 | N5: =D5/M5 -> 62369.254 | O5: 8 | P5: 200+200 | Q5: =400*M5 -> 8696.5928 | R5: =Q5*O5 -> 69572.742 | S5: =R5/1000 -> 69.572742
A6: Pasteurização | B6: 270 | C6: 60 | D6: =(B6*C6)/0.5 -> 32400 | E6: 6 | F6: 1 | G6: 0.4 | H6: =1.5*(E6-F6-G6) -> 6.9 | I6: 18 | J6: =I6/H6 -> 2.6086957 | K6: 15 | L6: =K6/H6 -> 2.173913 | M6: =J6*L6 -> 5.6710775 | N6: =D6/M6 -> 5713.2 | O6: 8 | P6: 60 | Q6: =P6*M6 -> 340.26465 | R6: =Q6*O6 -> 2722.1172 | S6: =R6/1000 -> 2.7221172
A7: Beneficiamento | B7: 1500 | C7: 850 | D7: =(B7*C7)/0.5 -> 2550000 | E7: 6 | F7: 1.4 | G7: 0.6 | H7: =1.5*(E7-F7-G7) -> 6 | I7: 50 | J7: =I7/H7 -> 8.3333333 | K7: 30 | L7: =K7/H7 -> 5 | M7: =J7*L7 -> 41.666667 | N7: =D7/M7 -> 61200 | O7: 8 | P7: 200+200 | Q7: =400*M7 -> 16666.667 | R7: =Q7*O7 -> 133333.33 | S7: =R7/1000 -> 133.33333
A8: Pre-estoque | B8: 225 | C8: 70 | D8: =(B8*C8)/0.5 -> 31500 | E8: 6 | F8: 0.7 | G8: 2.5 | H8: =1.5*(E8-F8-G8) -> 4.2 | I8: 15 | J8: =I8/H8 -> 3.5714286 | K8: 15 | L8: =K8/H8 -> 3.5714286 | M8: =J8*L8 -> 12.755102 | N8: =D8/M8 -> 2469.6 | O8: 8 | P8: 30 | Q8: =P8*M8 -> 382.65306 | R8: =Q8*O8 -> 3061.2245 | S8: =R8/1000 -> 3.0612245
A9: Estoque | B9: 225 | C9: 70 | D9: =(B9*C9)/0.5 -> 31500 | E9: 6 | F9: 0.7 | G9: 2.5 | H9: =1.5*(E9-F9-G9) -> 4.2 | I9: 15 | J9: =I9/H9 -> 3.5714286 | K9: 15 | L9: =K9/H9 -> 3.5714286 | M9: =J9*L9 -> 12.755102 | N9: =D9/M9 -> 2469.6 | O9: 8 | P9: 30 | Q9: =P9*M9 -> 382.65306 | R9: =Q9*O9 -> 3061.2245 | S9: =R9/1000 -> 3.0612245
A10: Entrada | B10: 452 | C10: 80 | D10: =(B10*C10)/0.5 -> 72320 | E10: 6 | F10: 1.6 | G10: 2 | H10: =1.5*(E10-F10-G10) -> 3.6 | I10: 30.15 | J10: =I10/H10 -> 8.375 | K10: 15 | L10: =K10/H10 -> 4.1666667 | M10: =J10*L10 -> 34.895833 | N10: =D10/M10 -> 2072.4537 | O10: 8 | P10: 30 | Q10: =P10*M10 -> 1046.875 | R10: =Q10*O10 -> 8375 | S10: =R10/1000 -> 8.375
A11: Area Auxiliar | B11: 448 | C11: 80 | D11: =(B11*C11)/0.5 -> 71680 | E11: 6 | F11: 1.6 | G11: 2 | H11: =1.5*(E11-F11-G11) -> 3.6 | I11: 31.85 | J11: =I11/H11 -> 8.8472222 | K11: 15 | L11: =K11/H11 -> 4.1666667 | M11: =J11*L11 -> 36.863426 | N11: =D11/M11 -> 1944.4747 | O11: 8 | P11: 30 | Q11: =P11*M11 -> 1105.9028 | R11: =Q11*O11 -> 8847.2222 | S11: =R11/1000 -> 8.8472222
R12: =SUM(R2:R11) -> 302095.77 | S12: =R12/1000 -> 302.09577
Q15: Tarifa para meio rural | R15: 0.53863
Q17: 1 hora | R17: =S12*R15 -> 162.71784
Q18: 8 horas | R18: =R17*8 -> 1301.7427
Q19: 1 dia de fabrica funcionando | R19: =((S2*4)*R15) +R18 -> 1443.6538

Sheet referencia
